urllib3.connectionpool - WARNING - Retrying (Retry(total=2, connect=None, read=None, redirect=None, status=None)) after connection broken by 'NewConnectionError('<urllib3.connection.HTTPConnection object at 0x00000227980668D0>: Failed to establish a new connection: [WinError 10061] Nenhuma conexão pôde ser feita porque a máquina de destino as recusou ativamente')': /session/4bb1c86b-47a4-44d8-90fc-2e989592a1a1
urllib3.connectionpool - WARNING - Retrying (Retry(total=1, connect=None, read=None, redirect=None, status=None)) after connection broken by 'NewConnectionError('<urllib3.connection.HTTPConnection object at 0x0000022798064F20>: Failed to establish a new connection: [WinError 10061] Nenhuma conexão pôde ser feita porque a máquina de destino as recusou ativamente')': /session/4bb1c86b-47a4-44d8-90fc-2e989592a1a1
urllib3.connectionpool - WARNING - Retrying (Retry(total=0, connect=None, read=None, redirect=None, status=None)) after connection broken by 'NewConnectionError('<urllib3.connection.HTTPConnection object at 0x0000022798066A50>: Failed to establish a new connection: [WinError 10061] Nenhuma conexão pôde ser feita porque a máquina de destino as recusou ativamente')': /session/4bb1c86b-47a4-44d8-90fc-2e989592a1a1
urllib3.connectionpool - WARNING - Retrying (Retry(total=2, connect=None, read=None, redirect=None, status=None)) after connection broken by 'NewConnectionError('<urllib3.connection.HTTPConnection object at 0x000001F39B2C8FE0>: Failed to establish a new connection: [WinError 10061] Nenhuma conexão pôde ser feita porque a máquina de destino as recusou ativamente')': /session/9e61f6b8-bc05-4a3e-ab33-a79b74916ccb
urllib3.connectionpool - WARNING - Retrying (Retry(total=1, connect=None, read=None, redirect=None, status=None)) after connection broken by 'NewConnectionError('<urllib3.connection.HTTPConnection object at 0x000001F39B2C9370>: Failed to establish a new connection: [WinError 10061] Nenhuma conexão pôde ser feita porque a máquina de destino as recusou ativamente')': /session/9e61f6b8-bc05-4a3e-ab33-a79b74916ccb
urllib3.connectionpool - WARNING - Retrying (Retry(total=0, connect=None, read=None, redirect=None, status=None)) after connection broken by 'NewConnectionError('<urllib3.connection.HTTPConnection object at 0x000001F39B2C94F0>: Failed to establish a new connection: [WinError 10061] Nenhuma conexão pôde ser feita porque a máquina de destino as recusou ativamente')': /session/9e61f6b8-bc05-4a3e-ab33-a79b74916ccb
urllib3.connectionpool - WARNING - Retrying (Retry(total=2, connect=None, read=None, redirect=None, status=None)) after connection broken by 'NewConnectionError('<urllib3.connection.HTTPConnection object at 0x000002280A71FB90>: Failed to establish a new connection: [WinError 10061] Nenhuma conexão pôde ser feita porque a máquina de destino as recusou ativamente')': /session/1556791a-ced0-49c0-8a7d-7ecc717e6be1
urllib3.connectionpool - WARNING - Retrying (Retry(total=1, connect=None, read=None, redirect=None, status=None)) after connection broken by 'NewConnectionError('<urllib3.connection.HTTPConnection object at 0x0000022845718080>: Failed to establish a new connection: [WinError 10061] Nenhuma conexão pôde ser feita porque a máquina de destino as recusou ativamente')': /session/1556791a-ced0-49c0-8a7d-7ecc717e6be1
urllib3.connectionpool - WARNING - Retrying (Retry(total=0, connect=None, read=None, redirect=None, status=None)) after connection broken by 'NewConnectionError('<urllib3.connection.HTTPConnection object at 0x0000022845718200>: Failed to establish a new connection: [WinError 10061] Nenhuma conexão pôde ser feita porque a máquina de destino as recusou ativamente')': /session/1556791a-ced0-49c0-8a7d-7ecc717e6be1
root - ERROR - Error executing query: DROP TABLE IF EXISTS controle_contratos, Error: database is locked
root - ERROR - Error executing query: DROP TABLE IF EXISTS controle_contratos, Error: database is locked
root - ERROR - Erro ao carregar tabela: 'GerenciarInclusaoExclusaoContratos' object has no attribute 'validate_and_process_data'
root - ERROR - Erro ao carregar tabela: 'GerenciarInclusaoExclusaoContratos' object has no attribute 'validate_and_process_data'
root - ERROR - Erro inesperado: Table 'controle_contratos' already exists.
root - ERROR - Error executing query: DROP TABLE IF EXISTS controle_contratos, Error: database is locked
root - ERROR - Error executing query: DROP TABLE IF EXISTS controle_contratos, Error: database is locked
root - ERROR - Error executing query: DROP TABLE IF EXISTS controle_contratos, Error: database is locked
root - ERROR - Error executing query: DROP TABLE IF EXISTS controle_contratos, Error: database is locked
httpx - INFO - HTTP Request: POST https://api.openai.com/v1/chat/completions "HTTP/1.1 401 Unauthorized"
root - ERROR - Erro ao carregar dados do banco de dados: can only concatenate str (not "int") to str
Traceback (most recent call last):
  File "c:\Users\Guilherme\Documents\360\licitacao360\modules\planejamento\utilidades_planejamento.py", line 551, in carregar_dados_pregao
    query = f"SELECT * FROM controle_processos WHERE id={index + 1}"
                                                         ~~~~~~^~~
TypeError: can only concatenate str (not "int") to str
root - ERROR - Erro ao carregar dados do banco de dados: Execution failed on sql 'SELECT * FROM controle_processos WHERE id=3': no such column: id
Traceback (most recent call last):
  File "C:\Users\Guilherme\Documents\360\licitacao360\venv\Lib\site-packages\pandas\io\sql.py", line 2674, in execute
    cur.execute(sql, *args)
sqlite3.OperationalError: no such column: id

The above exception was the direct cause of the following exception:

Traceback (most recent call last):
  File "c:\Users\Guilherme\Documents\360\licitacao360\modules\planejamento\utilidades_planejamento.py", line 529, in carregar_dados_pregao
    df_registro_selecionado = pd.read_sql_query(query, connection)
                              ^^^^^^^^^^^^^^^^^^^^^^^^^^^^^^^^^^^^
  File "C:\Users\Guilherme\Documents\360\licitacao360\venv\Lib\site-packages\pandas\io\sql.py", line 526, in read_sql_query
    return pandas_sql.read_query(
           ^^^^^^^^^^^^^^^^^^^^^^
  File "C:\Users\Guilherme\Documents\360\licitacao360\venv\Lib\site-packages\pandas\io\sql.py", line 2738, in read_query
    cursor = self.execute(sql, params)
             ^^^^^^^^^^^^^^^^^^^^^^^^^
  File "C:\Users\Guilherme\Documents\360\licitacao360\venv\Lib\site-packages\pandas\io\sql.py", line 2686, in execute
    raise ex from exc
pandas.errors.DatabaseError: Execution failed on sql 'SELECT * FROM controle_processos WHERE id=3': no such column: id
root - WARNING - Nenhum registro foi encontrado ou ocorreu um erro ao carregar os dados.
root - ERROR - Erro ao carregar dados do banco de dados: Execution failed on sql 'SELECT * FROM controle_processos WHERE id=5': no such column: id
Traceback (most recent call last):
  File "C:\Users\Guilherme\Documents\360\licitacao360\venv\Lib\site-packages\pandas\io\sql.py", line 2674, in execute
    cur.execute(sql, *args)
sqlite3.OperationalError: no such column: id

The above exception was the direct cause of the following exception:

Traceback (most recent call last):
  File "c:\Users\Guilherme\Documents\360\licitacao360\modules\planejamento\utilidades_planejamento.py", line 529, in carregar_dados_pregao
    df_registro_selecionado = pd.read_sql_query(query, connection)
                              ^^^^^^^^^^^^^^^^^^^^^^^^^^^^^^^^^^^^
  File "C:\Users\Guilherme\Documents\360\licitacao360\venv\Lib\site-packages\pandas\io\sql.py", line 526, in read_sql_query
    return pandas_sql.read_query(
           ^^^^^^^^^^^^^^^^^^^^^^
  File "C:\Users\Guilherme\Documents\360\licitacao360\venv\Lib\site-packages\pandas\io\sql.py", line 2738, in read_query
    cursor = self.execute(sql, params)
             ^^^^^^^^^^^^^^^^^^^^^^^^^
  File "C:\Users\Guilherme\Documents\360\licitacao360\venv\Lib\site-packages\pandas\io\sql.py", line 2686, in execute
    raise ex from exc
pandas.errors.DatabaseError: Execution failed on sql 'SELECT * FROM controle_processos WHERE id=5': no such column: id
root - WARNING - Nenhum registro foi encontrado ou ocorreu um erro ao carregar os dados.
root - ERROR - Erro ao carregar dados do banco de dados: Execution failed on sql 'SELECT * FROM controle_processos WHERE id=6': no such column: id
Traceback (most recent call last):
  File "C:\Users\Guilherme\Documents\360\licitacao360\venv\Lib\site-packages\pandas\io\sql.py", line 2674, in execute
    cur.execute(sql, *args)
sqlite3.OperationalError: no such column: id

The above exception was the direct cause of the following exception:

Traceback (most recent call last):
  File "c:\Users\Guilherme\Documents\360\licitacao360\modules\planejamento\utilidades_planejamento.py", line 529, in carregar_dados_pregao
    df_registro_selecionado = pd.read_sql_query(query, connection)
                              ^^^^^^^^^^^^^^^^^^^^^^^^^^^^^^^^^^^^
  File "C:\Users\Guilherme\Documents\360\licitacao360\venv\Lib\site-packages\pandas\io\sql.py", line 526, in read_sql_query
    return pandas_sql.read_query(
           ^^^^^^^^^^^^^^^^^^^^^^
  File "C:\Users\Guilherme\Documents\360\licitacao360\venv\Lib\site-packages\pandas\io\sql.py", line 2738, in read_query
    cursor = self.execute(sql, params)
             ^^^^^^^^^^^^^^^^^^^^^^^^^
  File "C:\Users\Guilherme\Documents\360\licitacao360\venv\Lib\site-packages\pandas\io\sql.py", line 2686, in execute
    raise ex from exc
pandas.errors.DatabaseError: Execution failed on sql 'SELECT * FROM controle_processos WHERE id=6': no such column: id
root - WARNING - Nenhum registro foi encontrado ou ocorreu um erro ao carregar os dados.
root - ERROR - Erro ao carregar dados do banco de dados: Execution failed on sql 'SELECT * FROM controle_processos WHERE id=7': no such column: id
Traceback (most recent call last):
  File "C:\Users\Guilherme\Documents\360\licitacao360\venv\Lib\site-packages\pandas\io\sql.py", line 2674, in execute
    cur.execute(sql, *args)
sqlite3.OperationalError: no such column: id

The above exception was the direct cause of the following exception:

Traceback (most recent call last):
  File "c:\Users\Guilherme\Documents\360\licitacao360\modules\planejamento\utilidades_planejamento.py", line 529, in carregar_dados_pregao
    df_registro_selecionado = pd.read_sql_query(query, connection)
                              ^^^^^^^^^^^^^^^^^^^^^^^^^^^^^^^^^^^^
  File "C:\Users\Guilherme\Documents\360\licitacao360\venv\Lib\site-packages\pandas\io\sql.py", line 526, in read_sql_query
    return pandas_sql.read_query(
           ^^^^^^^^^^^^^^^^^^^^^^
  File "C:\Users\Guilherme\Documents\360\licitacao360\venv\Lib\site-packages\pandas\io\sql.py", line 2738, in read_query
    cursor = self.execute(sql, params)
             ^^^^^^^^^^^^^^^^^^^^^^^^^
  File "C:\Users\Guilherme\Documents\360\licitacao360\venv\Lib\site-packages\pandas\io\sql.py", line 2686, in execute
    raise ex from exc
pandas.errors.DatabaseError: Execution failed on sql 'SELECT * FROM controle_processos WHERE id=7': no such column: id
root - WARNING - Nenhum registro foi encontrado ou ocorreu um erro ao carregar os dados.
root - ERROR - Erro ao carregar dados do banco de dados: Execution failed on sql 'SELECT * FROM controle_processos WHERE id=11': no such column: id
Traceback (most recent call last):
  File "C:\Users\Guilherme\Documents\360\licitacao360\venv\Lib\site-packages\pandas\io\sql.py", line 2674, in execute
    cur.execute(sql, *args)
sqlite3.OperationalError: no such column: id

The above exception was the direct cause of the following exception:

Traceback (most recent call last):
  File "c:\Users\Guilherme\Documents\360\licitacao360\modules\planejamento\utilidades_planejamento.py", line 529, in carregar_dados_pregao
    df_registro_selecionado = pd.read_sql_query(query, connection)
                              ^^^^^^^^^^^^^^^^^^^^^^^^^^^^^^^^^^^^
  File "C:\Users\Guilherme\Documents\360\licitacao360\venv\Lib\site-packages\pandas\io\sql.py", line 526, in read_sql_query
    return pandas_sql.read_query(
           ^^^^^^^^^^^^^^^^^^^^^^
  File "C:\Users\Guilherme\Documents\360\licitacao360\venv\Lib\site-packages\pandas\io\sql.py", line 2738, in read_query
    cursor = self.execute(sql, params)
             ^^^^^^^^^^^^^^^^^^^^^^^^^
  File "C:\Users\Guilherme\Documents\360\licitacao360\venv\Lib\site-packages\pandas\io\sql.py", line 2686, in execute
    raise ex from exc
pandas.errors.DatabaseError: Execution failed on sql 'SELECT * FROM controle_processos WHERE id=11': no such column: id
root - WARNING - Nenhum registro foi encontrado ou ocorreu um erro ao carregar os dados.
root - ERROR - Erro ao carregar dados do banco de dados: Execution failed on sql 'SELECT * FROM controle_processos WHERE id=12': no such column: id
Traceback (most recent call last):
  File "C:\Users\Guilherme\Documents\360\licitacao360\venv\Lib\site-packages\pandas\io\sql.py", line 2674, in execute
    cur.execute(sql, *args)
sqlite3.OperationalError: no such column: id

The above exception was the direct cause of the following exception:

Traceback (most recent call last):
  File "c:\Users\Guilherme\Documents\360\licitacao360\modules\planejamento\utilidades_planejamento.py", line 529, in carregar_dados_pregao
    df_registro_selecionado = pd.read_sql_query(query, connection)
                              ^^^^^^^^^^^^^^^^^^^^^^^^^^^^^^^^^^^^
  File "C:\Users\Guilherme\Documents\360\licitacao360\venv\Lib\site-packages\pandas\io\sql.py", line 526, in read_sql_query
    return pandas_sql.read_query(
           ^^^^^^^^^^^^^^^^^^^^^^
  File "C:\Users\Guilherme\Documents\360\licitacao360\venv\Lib\site-packages\pandas\io\sql.py", line 2738, in read_query
    cursor = self.execute(sql, params)
             ^^^^^^^^^^^^^^^^^^^^^^^^^
  File "C:\Users\Guilherme\Documents\360\licitacao360\venv\Lib\site-packages\pandas\io\sql.py", line 2686, in execute
    raise ex from exc
pandas.errors.DatabaseError: Execution failed on sql 'SELECT * FROM controle_processos WHERE id=12': no such column: id
root - WARNING - Nenhum registro foi encontrado ou ocorreu um erro ao carregar os dados.
root - WARNING - Nenhum registro foi encontrado ou ocorreu um erro ao carregar os dados.
root - WARNING - Nenhum registro foi encontrado ou ocorreu um erro ao carregar os dados.
root - WARNING - Nenhum registro foi encontrado ou ocorreu um erro ao carregar os dados.
root - ERROR - Erro ao carregar dados do banco de dados: can only concatenate str (not "int") to str
Traceback (most recent call last):
  File "c:\Users\Guilherme\Documents\360\licitacao360\modules\planejamento\utilidades_planejamento.py", line 527, in carregar_dados_pregao
    query = f"SELECT * FROM controle_processos WHERE id={index + 1}"
                                                         ~~~~~~^~~
TypeError: can only concatenate str (not "int") to str
root - ERROR - Erro ao carregar dados do banco de dados: can only concatenate str (not "int") to str
Traceback (most recent call last):
  File "c:\Users\Guilherme\Documents\360\licitacao360\modules\planejamento\utilidades_planejamento.py", line 527, in carregar_dados_pregao
    query = f"SELECT * FROM controle_processos WHERE id={index + 1}"
                                                         ~~~~~~^~~
TypeError: can only concatenate str (not "int") to str
root - ERROR - Erro ao carregar dados do banco de dados: Execution failed on sql 'SELECT * FROM controle_processos WHERE id=2': no such column: id
Traceback (most recent call last):
  File "C:\Users\Guilherme\Documents\360\licitacao360\venv\Lib\site-packages\pandas\io\sql.py", line 2674, in execute
    cur.execute(sql, *args)
sqlite3.OperationalError: no such column: id

The above exception was the direct cause of the following exception:

Traceback (most recent call last):
  File "c:\Users\Guilherme\Documents\360\licitacao360\modules\planejamento\utilidades_planejamento.py", line 529, in carregar_dados_pregao
    df_registro_selecionado = pd.read_sql_query(query, connection)
                              ^^^^^^^^^^^^^^^^^^^^^^^^^^^^^^^^^^^^
  File "C:\Users\Guilherme\Documents\360\licitacao360\venv\Lib\site-packages\pandas\io\sql.py", line 526, in read_sql_query
    return pandas_sql.read_query(
           ^^^^^^^^^^^^^^^^^^^^^^
  File "C:\Users\Guilherme\Documents\360\licitacao360\venv\Lib\site-packages\pandas\io\sql.py", line 2738, in read_query
    cursor = self.execute(sql, params)
             ^^^^^^^^^^^^^^^^^^^^^^^^^
  File "C:\Users\Guilherme\Documents\360\licitacao360\venv\Lib\site-packages\pandas\io\sql.py", line 2686, in execute
    raise ex from exc
pandas.errors.DatabaseError: Execution failed on sql 'SELECT * FROM controle_processos WHERE id=2': no such column: id
root - WARNING - Nenhum registro foi encontrado ou ocorreu um erro ao carregar os dados.
root - ERROR - Erro ao carregar dados do banco de dados: Execution failed on sql 'SELECT * FROM controle_processos WHERE id=6': no such column: id
Traceback (most recent call last):
  File "C:\Users\Guilherme\Documents\360\licitacao360\venv\Lib\site-packages\pandas\io\sql.py", line 2674, in execute
    cur.execute(sql, *args)
sqlite3.OperationalError: no such column: id

The above exception was the direct cause of the following exception:

Traceback (most recent call last):
  File "c:\Users\Guilherme\Documents\360\licitacao360\modules\planejamento\utilidades_planejamento.py", line 529, in carregar_dados_pregao
    df_registro_selecionado = pd.read_sql_query(query, connection)
                              ^^^^^^^^^^^^^^^^^^^^^^^^^^^^^^^^^^^^
  File "C:\Users\Guilherme\Documents\360\licitacao360\venv\Lib\site-packages\pandas\io\sql.py", line 526, in read_sql_query
    return pandas_sql.read_query(
           ^^^^^^^^^^^^^^^^^^^^^^
  File "C:\Users\Guilherme\Documents\360\licitacao360\venv\Lib\site-packages\pandas\io\sql.py", line 2738, in read_query
    cursor = self.execute(sql, params)
             ^^^^^^^^^^^^^^^^^^^^^^^^^
  File "C:\Users\Guilherme\Documents\360\licitacao360\venv\Lib\site-packages\pandas\io\sql.py", line 2686, in execute
    raise ex from exc
pandas.errors.DatabaseError: Execution failed on sql 'SELECT * FROM controle_processos WHERE id=6': no such column: id
root - WARNING - Nenhum registro foi encontrado ou ocorreu um erro ao carregar os dados.
root - ERROR - Erro ao carregar dados do banco de dados: can only concatenate str (not "int") to str
Traceback (most recent call last):
  File "c:\Users\Guilherme\Documents\360\licitacao360\modules\planejamento\utilidades_planejamento.py", line 527, in carregar_dados_pregao
    query = f"SELECT * FROM controle_processos WHERE id={index + 1}"
                                                         ~~~~~~^~~
TypeError: can only concatenate str (not "int") to str
root - ERROR - Erro ao carregar dados do banco de dados: Execution failed on sql 'SELECT * FROM controle_processos WHERE id=9': no such column: id
Traceback (most recent call last):
  File "C:\Users\Guilherme\Documents\360\licitacao360\venv\Lib\site-packages\pandas\io\sql.py", line 2674, in execute
    cur.execute(sql, *args)
sqlite3.OperationalError: no such column: id

The above exception was the direct cause of the following exception:

Traceback (most recent call last):
  File "c:\Users\Guilherme\Documents\360\licitacao360\modules\planejamento\utilidades_planejamento.py", line 529, in carregar_dados_pregao
    df_registro_selecionado = pd.read_sql_query(query, connection)
                              ^^^^^^^^^^^^^^^^^^^^^^^^^^^^^^^^^^^^
  File "C:\Users\Guilherme\Documents\360\licitacao360\venv\Lib\site-packages\pandas\io\sql.py", line 526, in read_sql_query
    return pandas_sql.read_query(
           ^^^^^^^^^^^^^^^^^^^^^^
  File "C:\Users\Guilherme\Documents\360\licitacao360\venv\Lib\site-packages\pandas\io\sql.py", line 2738, in read_query
    cursor = self.execute(sql, params)
             ^^^^^^^^^^^^^^^^^^^^^^^^^
  File "C:\Users\Guilherme\Documents\360\licitacao360\venv\Lib\site-packages\pandas\io\sql.py", line 2686, in execute
    raise ex from exc
pandas.errors.DatabaseError: Execution failed on sql 'SELECT * FROM controle_processos WHERE id=9': no such column: id
root - WARNING - Nenhum registro foi encontrado ou ocorreu um erro ao carregar os dados.
root - ERROR - Erro ao carregar dados do banco de dados: Execution failed on sql 'SELECT * FROM controle_processos WHERE id=4': no such column: id
Traceback (most recent call last):
  File "C:\Users\Guilherme\Documents\360\licitacao360\venv\Lib\site-packages\pandas\io\sql.py", line 2674, in execute
    cur.execute(sql, *args)
sqlite3.OperationalError: no such column: id

The above exception was the direct cause of the following exception:

Traceback (most recent call last):
  File "c:\Users\Guilherme\Documents\360\licitacao360\modules\planejamento\utilidades_planejamento.py", line 529, in carregar_dados_pregao
    df_registro_selecionado = pd.read_sql_query(query, connection)
                              ^^^^^^^^^^^^^^^^^^^^^^^^^^^^^^^^^^^^
  File "C:\Users\Guilherme\Documents\360\licitacao360\venv\Lib\site-packages\pandas\io\sql.py", line 526, in read_sql_query
    return pandas_sql.read_query(
           ^^^^^^^^^^^^^^^^^^^^^^
  File "C:\Users\Guilherme\Documents\360\licitacao360\venv\Lib\site-packages\pandas\io\sql.py", line 2738, in read_query
    cursor = self.execute(sql, params)
             ^^^^^^^^^^^^^^^^^^^^^^^^^
  File "C:\Users\Guilherme\Documents\360\licitacao360\venv\Lib\site-packages\pandas\io\sql.py", line 2686, in execute
    raise ex from exc
pandas.errors.DatabaseError: Execution failed on sql 'SELECT * FROM controle_processos WHERE id=4': no such column: id
root - WARNING - Nenhum registro foi encontrado ou ocorreu um erro ao carregar os dados.
root - ERROR - Erro ao carregar dados do banco de dados: Execution failed on sql 'SELECT * FROM controle_processos WHERE id=4': no such column: id
Traceback (most recent call last):
  File "C:\Users\Guilherme\Documents\360\licitacao360\venv\Lib\site-packages\pandas\io\sql.py", line 2674, in execute
    cur.execute(sql, *args)
sqlite3.OperationalError: no such column: id

The above exception was the direct cause of the following exception:

Traceback (most recent call last):
  File "c:\Users\Guilherme\Documents\360\licitacao360\modules\planejamento\utilidades_planejamento.py", line 529, in carregar_dados_pregao
    df_registro_selecionado = pd.read_sql_query(query, connection)
                              ^^^^^^^^^^^^^^^^^^^^^^^^^^^^^^^^^^^^
  File "C:\Users\Guilherme\Documents\360\licitacao360\venv\Lib\site-packages\pandas\io\sql.py", line 526, in read_sql_query
    return pandas_sql.read_query(
           ^^^^^^^^^^^^^^^^^^^^^^
  File "C:\Users\Guilherme\Documents\360\licitacao360\venv\Lib\site-packages\pandas\io\sql.py", line 2738, in read_query
    cursor = self.execute(sql, params)
             ^^^^^^^^^^^^^^^^^^^^^^^^^
  File "C:\Users\Guilherme\Documents\360\licitacao360\venv\Lib\site-packages\pandas\io\sql.py", line 2686, in execute
    raise ex from exc
pandas.errors.DatabaseError: Execution failed on sql 'SELECT * FROM controle_processos WHERE id=4': no such column: id
root - WARNING - Nenhum registro foi encontrado ou ocorreu um erro ao carregar os dados.
root - ERROR - Erro ao carregar dados do banco de dados: Execution failed on sql 'SELECT * FROM controle_processos WHERE id=5': no such column: id
Traceback (most recent call last):
  File "C:\Users\Guilherme\Documents\360\licitacao360\venv\Lib\site-packages\pandas\io\sql.py", line 2674, in execute
    cur.execute(sql, *args)
sqlite3.OperationalError: no such column: id

The above exception was the direct cause of the following exception:

Traceback (most recent call last):
  File "c:\Users\Guilherme\Documents\360\licitacao360\modules\planejamento\utilidades_planejamento.py", line 529, in carregar_dados_pregao
    df_registro_selecionado = pd.read_sql_query(query, connection)
                              ^^^^^^^^^^^^^^^^^^^^^^^^^^^^^^^^^^^^
  File "C:\Users\Guilherme\Documents\360\licitacao360\venv\Lib\site-packages\pandas\io\sql.py", line 526, in read_sql_query
    return pandas_sql.read_query(
           ^^^^^^^^^^^^^^^^^^^^^^
  File "C:\Users\Guilherme\Documents\360\licitacao360\venv\Lib\site-packages\pandas\io\sql.py", line 2738, in read_query
    cursor = self.execute(sql, params)
             ^^^^^^^^^^^^^^^^^^^^^^^^^
  File "C:\Users\Guilherme\Documents\360\licitacao360\venv\Lib\site-packages\pandas\io\sql.py", line 2686, in execute
    raise ex from exc
pandas.errors.DatabaseError: Execution failed on sql 'SELECT * FROM controle_processos WHERE id=5': no such column: id
root - WARNING - Nenhum registro foi encontrado ou ocorreu um erro ao carregar os dados.
root - ERROR - Erro ao carregar dados do banco de dados: Execution failed on sql 'SELECT * FROM controle_processos WHERE id=3': no such column: id
Traceback (most recent call last):
  File "C:\Users\Guilherme\Documents\360\licitacao360\venv\Lib\site-packages\pandas\io\sql.py", line 2674, in execute
    cur.execute(sql, *args)
sqlite3.OperationalError: no such column: id

The above exception was the direct cause of the following exception:

Traceback (most recent call last):
  File "c:\Users\Guilherme\Documents\360\licitacao360\modules\planejamento\utilidades_planejamento.py", line 529, in carregar_dados_pregao
    df_registro_selecionado = pd.read_sql_query(query, connection)
                              ^^^^^^^^^^^^^^^^^^^^^^^^^^^^^^^^^^^^
  File "C:\Users\Guilherme\Documents\360\licitacao360\venv\Lib\site-packages\pandas\io\sql.py", line 526, in read_sql_query
    return pandas_sql.read_query(
           ^^^^^^^^^^^^^^^^^^^^^^
  File "C:\Users\Guilherme\Documents\360\licitacao360\venv\Lib\site-packages\pandas\io\sql.py", line 2738, in read_query
    cursor = self.execute(sql, params)
             ^^^^^^^^^^^^^^^^^^^^^^^^^
  File "C:\Users\Guilherme\Documents\360\licitacao360\venv\Lib\site-packages\pandas\io\sql.py", line 2686, in execute
    raise ex from exc
pandas.errors.DatabaseError: Execution failed on sql 'SELECT * FROM controle_processos WHERE id=3': no such column: id
root - WARNING - Nenhum registro foi encontrado ou ocorreu um erro ao carregar os dados.
root - ERROR - Erro ao carregar dados do banco de dados: Execution failed on sql 'SELECT * FROM controle_processos WHERE id=8': no such column: id
Traceback (most recent call last):
  File "C:\Users\Guilherme\Documents\360\licitacao360\venv\Lib\site-packages\pandas\io\sql.py", line 2674, in execute
    cur.execute(sql, *args)
sqlite3.OperationalError: no such column: id

The above exception was the direct cause of the following exception:

Traceback (most recent call last):
  File "c:\Users\Guilherme\Documents\360\licitacao360\modules\planejamento\utilidades_planejamento.py", line 529, in carregar_dados_pregao
    df_registro_selecionado = pd.read_sql_query(query, connection)
                              ^^^^^^^^^^^^^^^^^^^^^^^^^^^^^^^^^^^^
  File "C:\Users\Guilherme\Documents\360\licitacao360\venv\Lib\site-packages\pandas\io\sql.py", line 526, in read_sql_query
    return pandas_sql.read_query(
           ^^^^^^^^^^^^^^^^^^^^^^
  File "C:\Users\Guilherme\Documents\360\licitacao360\venv\Lib\site-packages\pandas\io\sql.py", line 2738, in read_query
    cursor = self.execute(sql, params)
             ^^^^^^^^^^^^^^^^^^^^^^^^^
  File "C:\Users\Guilherme\Documents\360\licitacao360\venv\Lib\site-packages\pandas\io\sql.py", line 2686, in execute
    raise ex from exc
pandas.errors.DatabaseError: Execution failed on sql 'SELECT * FROM controle_processos WHERE id=8': no such column: id
root - WARNING - Nenhum registro foi encontrado ou ocorreu um erro ao carregar os dados.
root - ERROR - Erro ao carregar dados do banco de dados: Execution failed on sql 'SELECT * FROM controle_processos WHERE id=7': no such column: id
Traceback (most recent call last):
  File "C:\Users\Guilherme\Documents\360\licitacao360\venv\Lib\site-packages\pandas\io\sql.py", line 2674, in execute
    cur.execute(sql, *args)
sqlite3.OperationalError: no such column: id

The above exception was the direct cause of the following exception:

Traceback (most recent call last):
  File "c:\Users\Guilherme\Documents\360\licitacao360\modules\planejamento\utilidades_planejamento.py", line 529, in carregar_dados_pregao
    df_registro_selecionado = pd.read_sql_query(query, connection)
                              ^^^^^^^^^^^^^^^^^^^^^^^^^^^^^^^^^^^^
  File "C:\Users\Guilherme\Documents\360\licitacao360\venv\Lib\site-packages\pandas\io\sql.py", line 526, in read_sql_query
    return pandas_sql.read_query(
           ^^^^^^^^^^^^^^^^^^^^^^
  File "C:\Users\Guilherme\Documents\360\licitacao360\venv\Lib\site-packages\pandas\io\sql.py", line 2738, in read_query
    cursor = self.execute(sql, params)
             ^^^^^^^^^^^^^^^^^^^^^^^^^
  File "C:\Users\Guilherme\Documents\360\licitacao360\venv\Lib\site-packages\pandas\io\sql.py", line 2686, in execute
    raise ex from exc
pandas.errors.DatabaseError: Execution failed on sql 'SELECT * FROM controle_processos WHERE id=7': no such column: id
root - WARNING - Nenhum registro foi encontrado ou ocorreu um erro ao carregar os dados.
root - WARNING - A consulta retornou um DataFrame vazio.
root - WARNING - Nenhum registro foi encontrado ou ocorreu um erro ao carregar os dados.
root - WARNING - A consulta retornou um DataFrame vazio.
root - WARNING - Nenhum registro foi encontrado ou ocorreu um erro ao carregar os dados.
root - ERROR - A coluna 'justificativa' não foi encontrada no DataFrame.
root - ERROR - A coluna 'justificativa' não foi encontrada no DataFrame.
root - ERROR - A coluna 'justificativa' não foi encontrada no DataFrame.
root - ERROR - A coluna 'justificativa' não foi encontrada no DataFrame.
root - ERROR - A coluna 'justificativa' não foi encontrada no DataFrame.
root - ERROR - A coluna 'justificativa' não foi encontrada no DataFrame.
root - ERROR - A coluna 'justificativa' não foi encontrada no DataFrame.
root - ERROR - A coluna 'justificativa' não foi encontrada no DataFrame.
root - ERROR - A coluna 'justificativa' não foi encontrada no DataFrame.
root - ERROR - A coluna 'justificativa' não foi encontrada no DataFrame.
root - ERROR - A coluna 'justificativa' não foi encontrada no DataFrame.
root - ERROR - A coluna 'justificativa' não foi encontrada no DataFrame.
root - ERROR - A coluna 'justificativa' não foi encontrada no DataFrame.
root - ERROR - A coluna 'justificativa' não foi encontrada no DataFrame.
root - ERROR - A coluna 'justificativa' não foi encontrada no DataFrame.
root - ERROR - A coluna 'justificativa' não foi encontrada no DataFrame.
root - ERROR - A coluna 'justificativa' não foi encontrada no DataFrame.
root - ERROR - A coluna 'justificativa' não foi encontrada no DataFrame.
root - ERROR - A coluna 'justificativa' não foi encontrada no DataFrame.
root - ERROR - A coluna 'justificativa' não foi encontrada no DataFrame.
root - ERROR - A coluna 'justificativa' não foi encontrada no DataFrame.
root - ERROR - A coluna 'justificativa' não foi encontrada no DataFrame.
root - ERROR - A coluna 'justificativa' não foi encontrada no DataFrame.
root - ERROR - A coluna 'justificativa' não foi encontrada no DataFrame.
root - ERROR - A coluna 'justificativa' não foi encontrada no DataFrame.
root - ERROR - A coluna 'justificativa' não foi encontrada no DataFrame.
root - ERROR - A coluna 'justificativa' não foi encontrada no DataFrame.
root - ERROR - A coluna 'justificativa' não foi encontrada no DataFrame.
root - ERROR - A coluna 'justificativa' não foi encontrada no DataFrame.
root - ERROR - A coluna 'justificativa' não foi encontrada no DataFrame.
root - ERROR - A coluna 'justificativa' não foi encontrada no DataFrame.
root - ERROR - A coluna 'justificativa' não foi encontrada no DataFrame.
root - ERROR - A coluna 'justificativa' não foi encontrada no DataFrame.
root - ERROR - A coluna 'justificativa' não foi encontrada no DataFrame.
root - ERROR - A coluna 'justificativa' não foi encontrada no DataFrame.
root - ERROR - A coluna 'justificativa' não foi encontrada no DataFrame.
root - ERROR - A coluna 'justificativa' não foi encontrada no DataFrame.
root - ERROR - A coluna 'justificativa' não foi encontrada no DataFrame.
root - ERROR - A coluna 'justificativa' não foi encontrada no DataFrame.
root - ERROR - A coluna 'justificativa' não foi encontrada no DataFrame.
root - ERROR - A coluna 'justificativa' não foi encontrada no DataFrame.
root - ERROR - A coluna 'justificativa' não foi encontrada no DataFrame.
root - ERROR - A coluna 'justificativa' não foi encontrada no DataFrame.
root - ERROR - A coluna 'justificativa' não foi encontrada no DataFrame.
root - ERROR - A coluna 'justificativa' não foi encontrada no DataFrame.
root - ERROR - A coluna 'justificativa' não foi encontrada no DataFrame.
root - ERROR - A coluna 'justificativa' não foi encontrada no DataFrame.
root - ERROR - A coluna 'justificativa' não foi encontrada no DataFrame.
root - ERROR - A coluna 'justificativa' não foi encontrada no DataFrame.
root - ERROR - A coluna 'justificativa' não foi encontrada no DataFrame.
root - ERROR - A coluna 'justificativa' não foi encontrada no DataFrame.
root - WARNING - A consulta retornou um DataFrame vazio.
root - WARNING - Nenhum registro foi encontrado ou ocorreu um erro ao carregar os dados.
root - ERROR - A coluna 'justificativa' não foi encontrada no DataFrame.
root - ERROR - A coluna 'justificativa' não foi encontrada no DataFrame.
root - ERROR - A coluna 'justificativa' não foi encontrada no DataFrame.
root - ERROR - A coluna 'justificativa' não foi encontrada no DataFrame.
root - ERROR - A coluna 'justificativa' não foi encontrada no DataFrame.
root - ERROR - A coluna 'justificativa' não foi encontrada no DataFrame.
root - ERROR - A coluna 'justificativa' não foi encontrada no DataFrame.
root - ERROR - A coluna 'justificativa' não foi encontrada no DataFrame.
root - ERROR - A coluna 'justificativa' não foi encontrada no DataFrame.
root - ERROR - A coluna 'justificativa' não foi encontrada no DataFrame.
root - ERROR - A coluna 'justificativa' não foi encontrada no DataFrame.
root - ERROR - A coluna 'justificativa' não foi encontrada no DataFrame.
root - ERROR - A coluna 'justificativa' não foi encontrada no DataFrame.
root - ERROR - A coluna 'justificativa' não foi encontrada no DataFrame.
root - ERROR - A coluna 'justificativa' não foi encontrada no DataFrame.
root - ERROR - A coluna 'justificativa' não foi encontrada no DataFrame.
root - ERROR - A coluna 'justificativa' não foi encontrada no DataFrame.
root - ERROR - A coluna 'justificativa' não foi encontrada no DataFrame.
root - ERROR - A coluna 'justificativa' não foi encontrada no DataFrame.
root - ERROR - A coluna 'justificativa' não foi encontrada no DataFrame.
root - ERROR - A coluna 'justificativa' não foi encontrada no DataFrame.
root - ERROR - A coluna 'justificativa' não foi encontrada no DataFrame.
root - ERROR - A coluna 'justificativa' não foi encontrada no DataFrame.
root - ERROR - A coluna 'justificativa' não foi encontrada no DataFrame.
root - ERROR - A coluna 'justificativa' não foi encontrada no DataFrame.
root - ERROR - A coluna 'justificativa' não foi encontrada no DataFrame.
root - ERROR - A coluna 'justificativa' não foi encontrada no DataFrame.
root - ERROR - A coluna 'justificativa' não foi encontrada no DataFrame.
root - ERROR - A coluna 'justificativa' não foi encontrada no DataFrame.
root - ERROR - A coluna 'justificativa' não foi encontrada no DataFrame.
root - ERROR - A coluna 'justificativa' não foi encontrada no DataFrame.
root - ERROR - A coluna 'justificativa' não foi encontrada no DataFrame.
root - ERROR - A coluna 'justificativa' não foi encontrada no DataFrame.
root - ERROR - A coluna 'justificativa' não foi encontrada no DataFrame.
root - ERROR - A coluna 'justificativa' não foi encontrada no DataFrame.
root - ERROR - A coluna 'justificativa' não foi encontrada no DataFrame.
root - ERROR - A coluna 'justificativa' não foi encontrada no DataFrame.
root - ERROR - A coluna 'justificativa' não foi encontrada no DataFrame.
root - ERROR - A coluna 'justificativa' não foi encontrada no DataFrame.
root - ERROR - A coluna 'justificativa' não foi encontrada no DataFrame.
root - ERROR - A coluna 'justificativa' não foi encontrada no DataFrame.
root - ERROR - A coluna 'justificativa' não foi encontrada no DataFrame.
root - ERROR - A coluna 'justificativa' não foi encontrada no DataFrame.
root - ERROR - A coluna 'justificativa' não foi encontrada no DataFrame.
root - ERROR - A coluna 'justificativa' não foi encontrada no DataFrame.
root - ERROR - A coluna 'justificativa' não foi encontrada no DataFrame.
root - ERROR - A coluna 'justificativa' não foi encontrada no DataFrame.
root - ERROR - A coluna 'justificativa' não foi encontrada no DataFrame.
root - ERROR - A coluna 'justificativa' não foi encontrada no DataFrame.
root - ERROR - A coluna 'justificativa' não foi encontrada no DataFrame.
root - ERROR - A coluna 'justificativa' não foi encontrada no DataFrame.
root - ERROR - A coluna 'justificativa' não foi encontrada no DataFrame.
root - ERROR - A coluna 'justificativa' não foi encontrada no DataFrame.
root - ERROR - A coluna 'justificativa' não foi encontrada no DataFrame.
root - ERROR - A coluna 'justificativa' não foi encontrada no DataFrame.
root - ERROR - A coluna 'justificativa' não foi encontrada no DataFrame.
root - ERROR - A coluna 'justificativa' não foi encontrada no DataFrame.
root - ERROR - A coluna 'justificativa' não foi encontrada no DataFrame.
root - ERROR - A coluna 'justificativa' não foi encontrada no DataFrame.
root - ERROR - A coluna 'justificativa' não foi encontrada no DataFrame.
root - ERROR - A coluna 'justificativa' não foi encontrada no DataFrame.
root - ERROR - A coluna 'justificativa' não foi encontrada no DataFrame.
root - ERROR - A coluna 'justificativa' não foi encontrada no DataFrame.
root - ERROR - A coluna 'justificativa' não foi encontrada no DataFrame.
root - ERROR - A coluna 'justificativa' não foi encontrada no DataFrame.
root - ERROR - A coluna 'justificativa' não foi encontrada no DataFrame.
root - ERROR - A coluna 'justificativa' não foi encontrada no DataFrame.
root - ERROR - A coluna 'justificativa' não foi encontrada no DataFrame.
root - ERROR - A coluna 'justificativa' não foi encontrada no DataFrame.
root - ERROR - A coluna 'justificativa' não foi encontrada no DataFrame.
root - ERROR - A coluna 'justificativa' não foi encontrada no DataFrame.
root - ERROR - A coluna 'justificativa' não foi encontrada no DataFrame.
root - ERROR - A coluna 'justificativa' não foi encontrada no DataFrame.
root - ERROR - A coluna 'justificativa' não foi encontrada no DataFrame.
root - ERROR - A coluna 'justificativa' não foi encontrada no DataFrame.
root - ERROR - A coluna 'justificativa' não foi encontrada no DataFrame.
root - ERROR - A coluna 'justificativa' não foi encontrada no DataFrame.
root - ERROR - A coluna 'justificativa' não foi encontrada no DataFrame.
root - ERROR - A coluna 'justificativa' não foi encontrada no DataFrame.
root - ERROR - A coluna 'justificativa' não foi encontrada no DataFrame.
root - ERROR - A coluna 'justificativa' não foi encontrada no DataFrame.
root - ERROR - A coluna 'justificativa' não foi encontrada no DataFrame.
root - ERROR - A coluna 'justificativa' não foi encontrada no DataFrame.
root - ERROR - A coluna 'justificativa' não foi encontrada no DataFrame.
root - ERROR - A coluna 'justificativa' não foi encontrada no DataFrame.
root - ERROR - A coluna 'justificativa' não foi encontrada no DataFrame.
root - ERROR - A coluna 'justificativa' não foi encontrada no DataFrame.
root - ERROR - A coluna 'justificativa' não foi encontrada no DataFrame.
root - ERROR - A coluna 'justificativa' não foi encontrada no DataFrame.
root - ERROR - A coluna 'justificativa' não foi encontrada no DataFrame.
root - ERROR - A coluna 'justificativa' não foi encontrada no DataFrame.
root - ERROR - A coluna 'justificativa' não foi encontrada no DataFrame.
root - ERROR - A coluna 'justificativa' não foi encontrada no DataFrame.
root - ERROR - A coluna 'justificativa' não foi encontrada no DataFrame.
root - ERROR - A coluna 'justificativa' não foi encontrada no DataFrame.
root - ERROR - A coluna 'justificativa' não foi encontrada no DataFrame.
root - ERROR - A coluna 'justificativa' não foi encontrada no DataFrame.
root - ERROR - A coluna 'justificativa' não foi encontrada no DataFrame.
root - ERROR - A coluna 'justificativa' não foi encontrada no DataFrame.
root - ERROR - A coluna 'justificativa' não foi encontrada no DataFrame.
root - ERROR - A coluna 'justificativa' não foi encontrada no DataFrame.
root - ERROR - A coluna 'justificativa' não foi encontrada no DataFrame.
root - ERROR - A coluna 'justificativa' não foi encontrada no DataFrame.
root - ERROR - A coluna 'justificativa' não foi encontrada no DataFrame.
root - ERROR - A coluna 'justificativa' não foi encontrada no DataFrame.
root - ERROR - A coluna 'justificativa' não foi encontrada no DataFrame.
root - ERROR - A coluna 'justificativa' não foi encontrada no DataFrame.
root - ERROR - A coluna 'justificativa' não foi encontrada no DataFrame.
root - ERROR - A coluna 'justificativa' não foi encontrada no DataFrame.
root - ERROR - A coluna 'justificativa' não foi encontrada no DataFrame.
root - ERROR - A coluna 'justificativa' não foi encontrada no DataFrame.
root - ERROR - A coluna 'justificativa' não foi encontrada no DataFrame.
root - ERROR - A coluna 'justificativa' não foi encontrada no DataFrame.
root - ERROR - A coluna 'justificativa' não foi encontrada no DataFrame.
root - ERROR - A coluna 'justificativa' não foi encontrada no DataFrame.
root - ERROR - A coluna 'justificativa' não foi encontrada no DataFrame.
root - ERROR - A coluna 'justificativa' não foi encontrada no DataFrame.
root - ERROR - A coluna 'justificativa' não foi encontrada no DataFrame.
root - ERROR - A coluna 'justificativa' não foi encontrada no DataFrame.
root - ERROR - A coluna 'justificativa' não foi encontrada no DataFrame.
root - ERROR - A coluna 'justificativa' não foi encontrada no DataFrame.
root - ERROR - A coluna 'justificativa' não foi encontrada no DataFrame.
root - ERROR - A coluna 'justificativa' não foi encontrada no DataFrame.
root - ERROR - A coluna 'justificativa' não foi encontrada no DataFrame.
root - ERROR - A coluna 'justificativa' não foi encontrada no DataFrame.
root - ERROR - A coluna 'justificativa' não foi encontrada no DataFrame.
root - ERROR - A coluna 'justificativa' não foi encontrada no DataFrame.
root - ERROR - A coluna 'justificativa' não foi encontrada no DataFrame.
root - ERROR - A coluna 'justificativa' não foi encontrada no DataFrame.
root - ERROR - A coluna 'justificativa' não foi encontrada no DataFrame.
root - ERROR - A coluna 'justificativa' não foi encontrada no DataFrame.
root - ERROR - A coluna 'justificativa' não foi encontrada no DataFrame.
root - ERROR - A coluna 'justificativa' não foi encontrada no DataFrame.
root - ERROR - A coluna 'justificativa' não foi encontrada no DataFrame.
root - ERROR - A coluna 'justificativa' não foi encontrada no DataFrame.
root - ERROR - A coluna 'justificativa' não foi encontrada no DataFrame.
root - ERROR - A coluna 'justificativa' não foi encontrada no DataFrame.
root - ERROR - A coluna 'justificativa' não foi encontrada no DataFrame.
root - ERROR - A coluna 'justificativa' não foi encontrada no DataFrame.
root - ERROR - A coluna 'justificativa' não foi encontrada no DataFrame.
root - ERROR - A coluna 'justificativa' não foi encontrada no DataFrame.
root - ERROR - A coluna 'justificativa' não foi encontrada no DataFrame.
root - ERROR - A coluna 'justificativa' não foi encontrada no DataFrame.
root - ERROR - A coluna 'justificativa' não foi encontrada no DataFrame.
root - ERROR - A coluna 'justificativa' não foi encontrada no DataFrame.
root - ERROR - A coluna 'justificativa' não foi encontrada no DataFrame.
root - ERROR - A coluna 'justificativa' não foi encontrada no DataFrame.
root - ERROR - A coluna 'justificativa' não foi encontrada no DataFrame.
root - ERROR - A coluna 'justificativa' não foi encontrada no DataFrame.
root - ERROR - A coluna 'justificativa' não foi encontrada no DataFrame.
root - ERROR - A coluna 'justificativa' não foi encontrada no DataFrame.
root - ERROR - A coluna 'justificativa' não foi encontrada no DataFrame.
root - ERROR - A coluna 'justificativa' não foi encontrada no DataFrame.
root - ERROR - A coluna 'justificativa' não foi encontrada no DataFrame.
root - ERROR - A coluna 'justificativa' não foi encontrada no DataFrame.
root - ERROR - A coluna 'justificativa' não foi encontrada no DataFrame.
root - ERROR - A coluna 'justificativa' não foi encontrada no DataFrame.
root - ERROR - A coluna 'justificativa' não foi encontrada no DataFrame.
root - ERROR - A coluna 'justificativa' não foi encontrada no DataFrame.
root - ERROR - A coluna 'justificativa' não foi encontrada no DataFrame.
root - ERROR - A coluna 'justificativa' não foi encontrada no DataFrame.
root - ERROR - A coluna 'justificativa' não foi encontrada no DataFrame.
root - ERROR - A coluna 'justificativa' não foi encontrada no DataFrame.
root - ERROR - A coluna 'justificativa' não foi encontrada no DataFrame.
root - ERROR - A coluna 'justificativa' não foi encontrada no DataFrame.
root - ERROR - A coluna 'justificativa' não foi encontrada no DataFrame.
root - ERROR - A coluna 'justificativa' não foi encontrada no DataFrame.
root - ERROR - A coluna 'justificativa' não foi encontrada no DataFrame.
root - ERROR - A coluna 'justificativa' não foi encontrada no DataFrame.
root - ERROR - A coluna 'justificativa' não foi encontrada no DataFrame.
root - ERROR - A coluna 'justificativa' não foi encontrada no DataFrame.
root - ERROR - A coluna 'justificativa' não foi encontrada no DataFrame.
root - ERROR - A coluna 'justificativa' não foi encontrada no DataFrame.
root - ERROR - A coluna 'justificativa' não foi encontrada no DataFrame.
root - ERROR - A coluna 'justificativa' não foi encontrada no DataFrame.
root - ERROR - A coluna 'justificativa' não foi encontrada no DataFrame.
root - ERROR - A coluna 'justificativa' não foi encontrada no DataFrame.
root - ERROR - A coluna 'justificativa' não foi encontrada no DataFrame.
root - ERROR - A coluna 'justificativa' não foi encontrada no DataFrame.
root - ERROR - A coluna 'justificativa' não foi encontrada no DataFrame.
root - ERROR - A coluna 'justificativa' não foi encontrada no DataFrame.
root - ERROR - A coluna 'justificativa' não foi encontrada no DataFrame.
root - ERROR - A coluna 'justificativa' não foi encontrada no DataFrame.
root - ERROR - A coluna 'justificativa' não foi encontrada no DataFrame.
root - ERROR - A coluna 'justificativa' não foi encontrada no DataFrame.
root - ERROR - A coluna 'justificativa' não foi encontrada no DataFrame.
root - ERROR - A coluna 'justificativa' não foi encontrada no DataFrame.
root - ERROR - A coluna 'justificativa' não foi encontrada no DataFrame.
root - ERROR - A coluna 'justificativa' não foi encontrada no DataFrame.
root - ERROR - A coluna 'justificativa' não foi encontrada no DataFrame.
root - ERROR - A coluna 'justificativa' não foi encontrada no DataFrame.
root - ERROR - A coluna 'justificativa' não foi encontrada no DataFrame.
root - ERROR - A coluna 'justificativa' não foi encontrada no DataFrame.
root - ERROR - A coluna 'justificativa' não foi encontrada no DataFrame.
root - ERROR - A coluna 'justificativa' não foi encontrada no DataFrame.
root - ERROR - A coluna 'justificativa' não foi encontrada no DataFrame.
root - ERROR - A coluna 'justificativa' não foi encontrada no DataFrame.
root - ERROR - A coluna 'justificativa' não foi encontrada no DataFrame.
root - ERROR - A coluna 'justificativa' não foi encontrada no DataFrame.
root - ERROR - A coluna 'justificativa' não foi encontrada no DataFrame.
root - ERROR - A coluna 'justificativa' não foi encontrada no DataFrame.
root - ERROR - A coluna 'justificativa' não foi encontrada no DataFrame.
root - ERROR - A coluna 'justificativa' não foi encontrada no DataFrame.
root - ERROR - A coluna 'justificativa' não foi encontrada no DataFrame.
root - ERROR - A coluna 'justificativa' não foi encontrada no DataFrame.
root - ERROR - A coluna 'justificativa' não foi encontrada no DataFrame.
root - ERROR - A coluna 'justificativa' não foi encontrada no DataFrame.
root - ERROR - A coluna 'justificativa' não foi encontrada no DataFrame.
root - ERROR - A coluna 'justificativa' não foi encontrada no DataFrame.
root - ERROR - A coluna 'justificativa' não foi encontrada no DataFrame.
root - ERROR - A coluna 'justificativa' não foi encontrada no DataFrame.
root - ERROR - A coluna 'justificativa' não foi encontrada no DataFrame.
root - ERROR - A coluna 'justificativa' não foi encontrada no DataFrame.
root - ERROR - A coluna 'justificativa' não foi encontrada no DataFrame.
root - ERROR - A coluna 'justificativa' não foi encontrada no DataFrame.
root - ERROR - A coluna 'justificativa' não foi encontrada no DataFrame.
root - ERROR - A coluna 'justificativa' não foi encontrada no DataFrame.
root - ERROR - A coluna 'justificativa' não foi encontrada no DataFrame.
root - ERROR - A coluna 'justificativa' não foi encontrada no DataFrame.
root - ERROR - A coluna 'justificativa' não foi encontrada no DataFrame.
root - ERROR - A coluna 'justificativa' não foi encontrada no DataFrame.
root - ERROR - A coluna 'justificativa' não foi encontrada no DataFrame.
root - ERROR - A coluna 'justificativa' não foi encontrada no DataFrame.
root - ERROR - A coluna 'justificativa' não foi encontrada no DataFrame.
root - ERROR - A coluna 'justificativa' não foi encontrada no DataFrame.
root - ERROR - A coluna 'justificativa' não foi encontrada no DataFrame.
root - ERROR - A coluna 'justificativa' não foi encontrada no DataFrame.
root - ERROR - A coluna 'justificativa' não foi encontrada no DataFrame.
root - ERROR - A coluna 'justificativa' não foi encontrada no DataFrame.
root - ERROR - A coluna 'justificativa' não foi encontrada no DataFrame.
root - ERROR - A coluna 'justificativa' não foi encontrada no DataFrame.
root - ERROR - A coluna 'justificativa' não foi encontrada no DataFrame.
root - ERROR - A coluna 'justificativa' não foi encontrada no DataFrame.
root - ERROR - A coluna 'justificativa' não foi encontrada no DataFrame.
root - ERROR - A coluna 'justificativa' não foi encontrada no DataFrame.
root - ERROR - A coluna 'justificativa' não foi encontrada no DataFrame.
root - ERROR - A coluna 'justificativa' não foi encontrada no DataFrame.
root - ERROR - A coluna 'justificativa' não foi encontrada no DataFrame.
root - ERROR - A coluna 'justificativa' não foi encontrada no DataFrame.
root - ERROR - A coluna 'justificativa' não foi encontrada no DataFrame.
root - ERROR - A coluna 'justificativa' não foi encontrada no DataFrame.
root - ERROR - A coluna 'justificativa' não foi encontrada no DataFrame.
root - ERROR - A coluna 'justificativa' não foi encontrada no DataFrame.
root - ERROR - A coluna 'justificativa' não foi encontrada no DataFrame.
root - ERROR - A coluna 'justificativa' não foi encontrada no DataFrame.
root - ERROR - A coluna 'justificativa' não foi encontrada no DataFrame.
root - ERROR - A coluna 'justificativa' não foi encontrada no DataFrame.
root - ERROR - A coluna 'justificativa' não foi encontrada no DataFrame.
root - ERROR - A coluna 'justificativa' não foi encontrada no DataFrame.
root - ERROR - A coluna 'justificativa' não foi encontrada no DataFrame.
root - ERROR - A coluna 'justificativa' não foi encontrada no DataFrame.
root - ERROR - A coluna 'justificativa' não foi encontrada no DataFrame.
root - ERROR - A coluna 'justificativa' não foi encontrada no DataFrame.
root - ERROR - A coluna 'justificativa' não foi encontrada no DataFrame.
root - ERROR - A coluna 'justificativa' não foi encontrada no DataFrame.
root - ERROR - A coluna 'justificativa' não foi encontrada no DataFrame.
root - ERROR - A coluna 'justificativa' não foi encontrada no DataFrame.
root - ERROR - A coluna 'justificativa' não foi encontrada no DataFrame.
root - ERROR - A coluna 'justificativa' não foi encontrada no DataFrame.
root - ERROR - A coluna 'justificativa' não foi encontrada no DataFrame.
root - ERROR - A coluna 'justificativa' não foi encontrada no DataFrame.
root - ERROR - A coluna 'justificativa' não foi encontrada no DataFrame.
root - ERROR - A coluna 'justificativa' não foi encontrada no DataFrame.
root - ERROR - A coluna 'justificativa' não foi encontrada no DataFrame.
root - ERROR - A coluna 'justificativa' não foi encontrada no DataFrame.
root - ERROR - A coluna 'justificativa' não foi encontrada no DataFrame.
root - ERROR - A coluna 'justificativa' não foi encontrada no DataFrame.
root - ERROR - A coluna 'justificativa' não foi encontrada no DataFrame.
root - ERROR - A coluna 'justificativa' não foi encontrada no DataFrame.
root - ERROR - A coluna 'justificativa' não foi encontrada no DataFrame.
root - ERROR - A coluna 'justificativa' não foi encontrada no DataFrame.
root - ERROR - A coluna 'justificativa' não foi encontrada no DataFrame.
root - ERROR - A coluna 'justificativa' não foi encontrada no DataFrame.
root - ERROR - A coluna 'justificativa' não foi encontrada no DataFrame.
root - ERROR - A coluna 'justificativa' não foi encontrada no DataFrame.
root - ERROR - A coluna 'justificativa' não foi encontrada no DataFrame.
root - ERROR - A coluna 'justificativa' não foi encontrada no DataFrame.
root - ERROR - A coluna 'justificativa' não foi encontrada no DataFrame.
root - ERROR - A coluna 'justificativa' não foi encontrada no DataFrame.
root - ERROR - A coluna 'justificativa' não foi encontrada no DataFrame.
root - ERROR - A coluna 'justificativa' não foi encontrada no DataFrame.
root - ERROR - A coluna 'justificativa' não foi encontrada no DataFrame.
root - ERROR - A coluna 'justificativa' não foi encontrada no DataFrame.
root - ERROR - A coluna 'justificativa' não foi encontrada no DataFrame.
root - ERROR - A coluna 'justificativa' não foi encontrada no DataFrame.
root - ERROR - A coluna 'justificativa' não foi encontrada no DataFrame.
root - ERROR - A coluna 'justificativa' não foi encontrada no DataFrame.
root - ERROR - A coluna 'justificativa' não foi encontrada no DataFrame.
root - ERROR - A coluna 'justificativa' não foi encontrada no DataFrame.
root - ERROR - A coluna 'justificativa' não foi encontrada no DataFrame.
root - ERROR - A coluna 'justificativa' não foi encontrada no DataFrame.
root - ERROR - A coluna 'justificativa' não foi encontrada no DataFrame.
root - ERROR - A coluna 'justificativa' não foi encontrada no DataFrame.
root - ERROR - A coluna 'justificativa' não foi encontrada no DataFrame.
root - ERROR - A coluna 'justificativa' não foi encontrada no DataFrame.
root - ERROR - A coluna 'justificativa' não foi encontrada no DataFrame.
root - ERROR - A coluna 'justificativa' não foi encontrada no DataFrame.
root - ERROR - A coluna 'justificativa' não foi encontrada no DataFrame.
root - ERROR - A coluna 'justificativa' não foi encontrada no DataFrame.
root - ERROR - A coluna 'justificativa' não foi encontrada no DataFrame.
root - ERROR - A coluna 'justificativa' não foi encontrada no DataFrame.
root - ERROR - A coluna 'justificativa' não foi encontrada no DataFrame.
root - ERROR - A coluna 'justificativa' não foi encontrada no DataFrame.
root - ERROR - A coluna 'justificativa' não foi encontrada no DataFrame.
root - ERROR - A coluna 'justificativa' não foi encontrada no DataFrame.
root - ERROR - A coluna 'justificativa' não foi encontrada no DataFrame.
root - ERROR - A coluna 'justificativa' não foi encontrada no DataFrame.
root - ERROR - A coluna 'justificativa' não foi encontrada no DataFrame.
root - ERROR - A coluna 'justificativa' não foi encontrada no DataFrame.
root - ERROR - A coluna 'justificativa' não foi encontrada no DataFrame.
root - ERROR - A coluna 'justificativa' não foi encontrada no DataFrame.
root - ERROR - A coluna 'justificativa' não foi encontrada no DataFrame.
root - ERROR - A coluna 'justificativa' não foi encontrada no DataFrame.
root - ERROR - A coluna 'justificativa' não foi encontrada no DataFrame.
root - ERROR - A coluna 'justificativa' não foi encontrada no DataFrame.
root - ERROR - A coluna 'justificativa' não foi encontrada no DataFrame.
root - ERROR - A coluna 'justificativa' não foi encontrada no DataFrame.
root - ERROR - A coluna 'justificativa' não foi encontrada no DataFrame.
root - ERROR - A coluna 'justificativa' não foi encontrada no DataFrame.
root - ERROR - A coluna 'justificativa' não foi encontrada no DataFrame.
root - ERROR - A coluna 'justificativa' não foi encontrada no DataFrame.
root - ERROR - A coluna 'justificativa' não foi encontrada no DataFrame.
root - ERROR - A coluna 'justificativa' não foi encontrada no DataFrame.
root - ERROR - A coluna 'justificativa' não foi encontrada no DataFrame.
root - ERROR - A coluna 'justificativa' não foi encontrada no DataFrame.
root - ERROR - A coluna 'justificativa' não foi encontrada no DataFrame.
root - ERROR - A coluna 'justificativa' não foi encontrada no DataFrame.
root - ERROR - A coluna 'justificativa' não foi encontrada no DataFrame.
root - ERROR - A coluna 'justificativa' não foi encontrada no DataFrame.
root - ERROR - A coluna 'justificativa' não foi encontrada no DataFrame.
root - ERROR - A coluna 'justificativa' não foi encontrada no DataFrame.
root - ERROR - A coluna 'justificativa' não foi encontrada no DataFrame.
root - ERROR - A coluna 'justificativa' não foi encontrada no DataFrame.
root - ERROR - A coluna 'justificativa' não foi encontrada no DataFrame.
root - ERROR - A coluna 'justificativa' não foi encontrada no DataFrame.
root - ERROR - A coluna 'justificativa' não foi encontrada no DataFrame.
root - ERROR - A coluna 'justificativa' não foi encontrada no DataFrame.
root - ERROR - A coluna 'justificativa' não foi encontrada no DataFrame.
root - ERROR - A coluna 'justificativa' não foi encontrada no DataFrame.
root - ERROR - A coluna 'justificativa' não foi encontrada no DataFrame.
root - ERROR - A coluna 'justificativa' não foi encontrada no DataFrame.
root - ERROR - A coluna 'justificativa' não foi encontrada no DataFrame.
root - ERROR - A coluna 'justificativa' não foi encontrada no DataFrame.
root - ERROR - A coluna 'justificativa' não foi encontrada no DataFrame.
root - ERROR - A coluna 'justificativa' não foi encontrada no DataFrame.
root - ERROR - A coluna 'justificativa' não foi encontrada no DataFrame.
root - ERROR - A coluna 'justificativa' não foi encontrada no DataFrame.
root - ERROR - A coluna 'justificativa' não foi encontrada no DataFrame.
root - ERROR - A coluna 'justificativa' não foi encontrada no DataFrame.
root - ERROR - A coluna 'justificativa' não foi encontrada no DataFrame.
root - ERROR - A coluna 'justificativa' não foi encontrada no DataFrame.
root - ERROR - A coluna 'justificativa' não foi encontrada no DataFrame.
root - ERROR - A coluna 'justificativa' não foi encontrada no DataFrame.
root - ERROR - A coluna 'justificativa' não foi encontrada no DataFrame.
root - ERROR - A coluna 'justificativa' não foi encontrada no DataFrame.
root - ERROR - A coluna 'justificativa' não foi encontrada no DataFrame.
root - ERROR - A coluna 'justificativa' não foi encontrada no DataFrame.
root - ERROR - A coluna 'justificativa' não foi encontrada no DataFrame.
root - ERROR - A coluna 'justificativa' não foi encontrada no DataFrame.
root - ERROR - A coluna 'justificativa' não foi encontrada no DataFrame.
root - ERROR - A coluna 'justificativa' não foi encontrada no DataFrame.
root - ERROR - A coluna 'justificativa' não foi encontrada no DataFrame.
root - ERROR - A coluna 'justificativa' não foi encontrada no DataFrame.
root - ERROR - A coluna 'justificativa' não foi encontrada no DataFrame.
root - ERROR - A coluna 'justificativa' não foi encontrada no DataFrame.
root - ERROR - A coluna 'justificativa' não foi encontrada no DataFrame.
root - ERROR - A coluna 'justificativa' não foi encontrada no DataFrame.
root - ERROR - A coluna 'justificativa' não foi encontrada no DataFrame.
root - ERROR - A coluna 'justificativa' não foi encontrada no DataFrame.
root - ERROR - A coluna 'justificativa' não foi encontrada no DataFrame.
root - ERROR - A coluna 'justificativa' não foi encontrada no DataFrame.
root - ERROR - A coluna 'justificativa' não foi encontrada no DataFrame.
root - ERROR - A coluna 'justificativa' não foi encontrada no DataFrame.
root - ERROR - A coluna 'justificativa' não foi encontrada no DataFrame.
root - ERROR - A coluna 'justificativa' não foi encontrada no DataFrame.
root - ERROR - A coluna 'justificativa' não foi encontrada no DataFrame.
root - ERROR - A coluna 'justificativa' não foi encontrada no DataFrame.
root - ERROR - A coluna 'justificativa' não foi encontrada no DataFrame.
root - ERROR - A coluna 'justificativa' não foi encontrada no DataFrame.
root - ERROR - A coluna 'justificativa' não foi encontrada no DataFrame.
root - ERROR - A coluna 'justificativa' não foi encontrada no DataFrame.
root - ERROR - A coluna 'justificativa' não foi encontrada no DataFrame.
root - ERROR - A coluna 'justificativa' não foi encontrada no DataFrame.
root - ERROR - A coluna 'justificativa' não foi encontrada no DataFrame.
